"""fixing insights.personal_goal_id error

Revision ID: 207128732a2b
Revises: 4c4213eb5c43
Create Date: 2024-03-21 16:33:34.683937

"""
from alembic import op
import sqlalchemy as sa


# revision identifiers, used by Alembic.
revision = '207128732a2b'
down_revision = '4c4213eb5c43'
branch_labels = None
depends_on = None


def upgrade():
    # ### commands auto generated by Alembic - please adjust! ###
    with op.batch_alter_table('insights', schema=None) as batch_op:
        batch_op.add_column(sa.Column('personal_goal_id', sa.Integer(), nullable=True))
        batch_op.create_foreign_key(batch_op.f('fk_insights_personal_goal_id_personal_goals'), 'personal_goals', ['personal_goal_id'], ['id'])

    # ### end Alembic commands ###


def downgrade():
    # ### commands auto generated by Alembic - please adjust! ###
    with op.batch_alter_table('insights', schema=None) as batch_op:
        batch_op.drop_constraint(batch_op.f('fk_insights_personal_goal_id_personal_goals'), type_='foreignkey')
        batch_op.drop_column('personal_goal_id')

    # ### end Alembic commands ###
